<?xml version="1.0" encoding="UTF-8"?>
<!-- Generated by org.testng.reporters.JUnitReportReporter -->
<testsuite hostname="DESKTOP-BDABQQ0" failures="1" tests="6" name="test_Package.Test_Class1" time="6.575" errors="1" timestamp="2023-07-08T17:06:41 IST" skipped="1">
  <testcase classname="test_Package.Test_Class1" name="AfterMethod" time="0.632">
    <error type="java.lang.NullPointerException">
      <![CDATA[java.lang.NullPointerException
at java.base/java.io.File.<init>(File.java:278)
at testUtility.Screenshot.ScreenShotCaptureMethod(Screenshot.java:18)
at test_Package.BaseClass.AfterMethod(BaseClass.java:48)
at java.base/jdk.internal.reflect.DirectMethodHandleAccessor.invoke(DirectMethodHandleAccessor.java:104)
at java.base/java.lang.reflect.Method.invoke(Method.java:578)
at org.testng.internal.MethodInvocationHelper.invokeMethod(MethodInvocationHelper.java:133)
at org.testng.internal.MethodInvocationHelper.invokeMethodConsideringTimeout(MethodInvocationHelper.java:62)
at org.testng.internal.ConfigInvoker.invokeConfigurationMethod(ConfigInvoker.java:385)
at org.testng.internal.ConfigInvoker.invokeConfigurations(ConfigInvoker.java:321)
at org.testng.internal.TestInvoker.runConfigMethods(TestInvoker.java:700)
at org.testng.internal.TestInvoker.runAfterGroupsConfigurations(TestInvoker.java:676)
at org.testng.internal.TestInvoker.invokeMethod(TestInvoker.java:660)
at org.testng.internal.TestInvoker.invokeTestMethod(TestInvoker.java:173)
at org.testng.internal.MethodRunner.runInSequence(MethodRunner.java:46)
at org.testng.internal.TestInvoker$MethodInvocationAgent.invoke(TestInvoker.java:824)
at org.testng.internal.TestInvoker.invokeTestMethods(TestInvoker.java:146)
at org.testng.internal.TestMethodWorker.invokeTestMethods(TestMethodWorker.java:146)
at org.testng.internal.TestMethodWorker.run(TestMethodWorker.java:128)
at java.base/java.util.ArrayList.forEach(ArrayList.java:1511)
at org.testng.TestRunner.privateRun(TestRunner.java:794)
at org.testng.TestRunner.run(TestRunner.java:596)
at org.testng.SuiteRunner.runTest(SuiteRunner.java:377)
at org.testng.SuiteRunner.runSequentially(SuiteRunner.java:371)
at org.testng.SuiteRunner.privateRun(SuiteRunner.java:332)
at org.testng.SuiteRunner.run(SuiteRunner.java:276)
at org.testng.SuiteRunnerWorker.runSuite(SuiteRunnerWorker.java:53)
at org.testng.SuiteRunnerWorker.run(SuiteRunnerWorker.java:96)
at org.testng.TestNG.runSuitesSequentially(TestNG.java:1212)
at org.testng.TestNG.runSuitesLocally(TestNG.java:1134)
at org.testng.TestNG.runSuites(TestNG.java:1063)
at org.testng.TestNG.run(TestNG.java:1031)
at org.testng.remote.AbstractRemoteTestNG.run(AbstractRemoteTestNG.java:115)
at org.testng.remote.RemoteTestNG.initAndRun(RemoteTestNG.java:251)
at org.testng.remote.RemoteTestNG.main(RemoteTestNG.java:77)
]]>
    </error>
  </testcase> <!-- AfterMethod -->
  <system-out/>
  <testcase classname="test_Package.Test_Class1" name="test2" time="0.211"/>
  <system-out/>
  <testcase classname="test_Package.Test_Class1" name="test1" time="0.941"/>
  <system-out/>
  <testcase classname="test_Package.Test_Class1" name="test3" time="0.018"/>
  <system-out/>
  <testcase classname="test_Package.Test_Class1" name="verifyDashboardElement" time="4.773">
    <failure message="expected:&lt;https://opensource-demo.orangehrmlive.com/web/index.php/dashboard/index&gt; but was:&lt;https://opensource-demo.orangehrmlive.com/web/index.php/auth/login&gt;" type="java.lang.AssertionError">
      <![CDATA[java.lang.AssertionError: expected:<https://opensource-demo.orangehrmlive.com/web/index.php/dashboard/index> but was:<https://opensource-demo.orangehrmlive.com/web/index.php/auth/login>
at org.testng.AssertJUnit.assertEquals(AssertJUnit.java:115)
at org.testng.AssertJUnit.assertEquals(AssertJUnit.java:125)
at test_Package.Test_Class1.verifyDashboardElement(Test_Class1.java:84)
at java.base/jdk.internal.reflect.DirectMethodHandleAccessor.invoke(DirectMethodHandleAccessor.java:104)
at java.base/java.lang.reflect.Method.invoke(Method.java:578)
at org.testng.internal.MethodInvocationHelper.invokeMethod(MethodInvocationHelper.java:133)
at org.testng.internal.TestInvoker.invokeMethod(TestInvoker.java:598)
at org.testng.internal.TestInvoker.invokeTestMethod(TestInvoker.java:173)
at org.testng.internal.MethodRunner.runInSequence(MethodRunner.java:46)
at org.testng.internal.TestInvoker$MethodInvocationAgent.invoke(TestInvoker.java:824)
at org.testng.internal.TestInvoker.invokeTestMethods(TestInvoker.java:146)
at org.testng.internal.TestMethodWorker.invokeTestMethods(TestMethodWorker.java:146)
at org.testng.internal.TestMethodWorker.run(TestMethodWorker.java:128)
at java.base/java.util.ArrayList.forEach(ArrayList.java:1511)
at org.testng.TestRunner.privateRun(TestRunner.java:794)
at org.testng.TestRunner.run(TestRunner.java:596)
at org.testng.SuiteRunner.runTest(SuiteRunner.java:377)
at org.testng.SuiteRunner.runSequentially(SuiteRunner.java:371)
at org.testng.SuiteRunner.privateRun(SuiteRunner.java:332)
at org.testng.SuiteRunner.run(SuiteRunner.java:276)
at org.testng.SuiteRunnerWorker.runSuite(SuiteRunnerWorker.java:53)
at org.testng.SuiteRunnerWorker.run(SuiteRunnerWorker.java:96)
at org.testng.TestNG.runSuitesSequentially(TestNG.java:1212)
at org.testng.TestNG.runSuitesLocally(TestNG.java:1134)
at org.testng.TestNG.runSuites(TestNG.java:1063)
at org.testng.TestNG.run(TestNG.java:1031)
at org.testng.remote.AbstractRemoteTestNG.run(AbstractRemoteTestNG.java:115)
at org.testng.remote.RemoteTestNG.initAndRun(RemoteTestNG.java:251)
at org.testng.remote.RemoteTestNG.main(RemoteTestNG.java:77)
]]>
    </failure>
  </testcase> <!-- verifyDashboardElement -->
  <system-out/>
  <testcase classname="test_Package.Test_Class1" name="abcd" time="0.000">
    <skipped/>
  </testcase> <!-- abcd -->
  <system-out/>
</testsuite> <!-- test_Package.Test_Class1 -->
